<?xml version="1.0"?>
<robot xmlns:xacro="http://ros.org/wiki/xacro" name="latty_chassis">

  <!-- Parameters -->
  <xacro:property name="wheel_radius" value="0.1"/>
  <xacro:property name="wheel_length" value="0.06"/>
  <xacro:property name="front_wheel_radius" value="0.03"/>
  <xacro:property name="front_wheel_length" value="0.02"/>
  <xacro:property name="wheelbase" value="0.25"/>

  <link name="base_link"/>

  <!-- Chassis -->
  <link name="chassis">

    <inertial>
      <origin xyz="0 0 0.05" rpy="0 0 0"/>
      <mass value="30.0"/>
      <inertia ixx="1.25" iyy="4.25" izz="5.0" ixy="0" ixz="0" iyz="0"/>
    </inertial>

    <visual>
      <origin xyz="0 0 0.1" rpy="0 0 0"/>
      <geometry>
        <box size="0.4 0.2 0.1"/>
      </geometry>
    </visual>

    <collision>
      <origin xyz="0 0 0.1" rpy="0 0 0"/>
      <geometry>
        <box size="0.4 0.2 0.1"/>
      </geometry>
    </collision>
  </link>

  <!-- Knuckle -->
  <link name="steer_knuckle">

    <inertial>
      <origin xyz="0 0 0" rpy="0 0 0"/>
      <mass value="0.5"/>
      <inertia ixx="0.001" iyy="0.001" izz="0.001" ixy="0" ixz="0" iyz="0"/>
    </inertial>

    <visual>
      <origin xyz="0 0 0" rpy="0 0 0"/>
      <geometry>
        <box size="0.03 0.02 0.04"/>
      </geometry>
    </visual>

    <collision>
      <origin xyz="0 0 0" rpy="0 0 0"/>
      <geometry>
        <box size="0.03 0.02 0.04"/>
      </geometry>
    </collision>

  </link>

  <!-- Front left wheel -->
  <link name="front_left_wheel">

    <inertial>
      <mass value="1.5"/>
      <inertia ixx="0.000388" iyy="0.000388" izz="0.000675" ixy="0.0" ixz="0.0" iyz="0.0"/>
    </inertial>

    <visual>
      <origin xyz="0 0 0" rpy="0 1.5707 1.5707"/>
      <geometry>
        <cylinder length="${front_wheel_length}" radius="${front_wheel_radius}"/>
      </geometry>
    </visual>

    <collision>
      <origin xyz="0 0 0" rpy="0 1.5707 1.5707"/>
      <geometry>
        <cylinder length="${front_wheel_length}" radius="${front_wheel_radius}"/>
      </geometry>
    </collision>

  </link>

  <!-- Front right wheel -->
  <link name="front_right_wheel">

    <inertial>
      <mass value="1.5"/>
      <inertia ixx="0.000388" iyy="0.000388" izz="0.000675" ixy="0.0" ixz="0.0" iyz="0.0"/>
    </inertial>

    <visual>
      <origin xyz="0 0 0" rpy="0 1.5707 1.5707"/>
      <geometry>
        <cylinder length="${front_wheel_length}" radius="${front_wheel_radius}"/>
      </geometry>
    </visual>

    <collision>
      <origin xyz="0 0 0" rpy="0 1.5707 1.5707"/>
      <geometry>
        <cylinder length="${front_wheel_length}" radius="${front_wheel_radius}"/>
      </geometry>
    </collision>

  </link>

  <!-- Rear Wheels -->
  <link name="left_wheel">

    <inertial>
      <mass value="5.0"/>
      <inertia ixx="0.0143" iyy="0.0143" izz="0.025" ixy="0.0" ixz="0.0" iyz="0.0"/>
    </inertial>

    <visual>
      <origin xyz="0 0 0" rpy="0 1.5707 1.5707"/>
      <geometry>
        <cylinder length="${wheel_length}" radius="${wheel_radius}"/>
      </geometry>
    </visual>

    <collision>
      <origin xyz="0 0 0" rpy="0 1.5707 1.5707"/>
      <geometry>
        <cylinder length="${wheel_length}" radius="${wheel_radius}"/>
      </geometry>
    </collision>

  </link>

  <link name="right_wheel">
    
    <inertial>
      <mass value="5.0"/>
      <inertia ixx="0.0143" iyy="0.0143" izz="0.025" ixy="0.0" ixz="0.0" iyz="0.0"/>
    </inertial>
    
    <visual>
      <origin xyz="0 0 0" rpy="0 1.5707 1.5707"/>
      <geometry>
        <cylinder length="${wheel_length}" radius="${wheel_radius}"/>
      </geometry>
    </visual>

    <collision>
      <origin xyz="0 0 0" rpy="0 1.5707 1.5707"/>
      <geometry>
        <cylinder length="${wheel_length}" radius="${wheel_radius}"/>
      </geometry>
    </collision>

  </link>

  <!-- IMU -->
  <link name="imu_link">
    
    <collision>
      <origin xyz="0 0 0" rpy="0 0 0"/>
      <geometry>
        <box size="0.02 0.02 0.01"/>
      </geometry>
    </collision>

    <inertial>
      <origin xyz="0 0 0"  rpy="0 0 0"/>
      <mass value="0.01"/>
      <inertia ixx="1e-6" iyy="1e-6" izz="1e-6" ixy="0" ixz="0" iyz="0"/>
    </inertial>

    <visual>
      <origin xyz="0 0 0" rpy="0 0 0"/>
      <geometry>
        <box size="0.05 0.05 0.02"/>
      </geometry>
    </visual>
  </link>
  

  <!-- Gazebo material overrides -->
  <gazebo reference="chassis">
    <material>Gazebo/Yellow</material>
  </gazebo>

  <gazebo reference="left_wheel">
    <material>Gazebo/Black</material>
    <mu1>1.0</mu1>
    <mu2>1.0</mu2>
    <kp>1000000.0</kp>
    <kd>1.0</kd>
  </gazebo>

  <gazebo reference="right_wheel">
    <material>Gazebo/Black</material>
    <mu1>1.0</mu1>
    <mu2>1.0</mu2>
    <kp>1000000.0</kp>  
    <kd>1.0</kd>
  </gazebo>

  <gazebo reference="steer_knuckle">
    <material>Gazebo/Grey</material>
    <mu1>0.1</mu1>    <!-- Low friction coefficient -->
    <mu2>0.1</mu2>    <!-- Low friction coefficient -->
  </gazebo>

  <gazebo reference="front_left_wheel">
    <material>Gazebo/Black</material>
    <mu1>1.0</mu1>
    <mu2>1.0</mu2>
    <kp>1000000.0</kp>
    <kd>1.0</kd>
  </gazebo>

  <gazebo reference="front_right_wheel">
    <material>Gazebo/Black</material>
    <mu1>1.0</mu1>
    <mu2>1.0</mu2>
    <kp>1000000.0</kp>
    <kd>1.0</kd>
  </gazebo>

  <gazebo reference="imu_link">
    <material>Gazebo/Grey</material>
  </gazebo>

  <!-- Joints -->

  <joint name="base_to_chassis" type="fixed">
    <parent link="base_link"/>
    <child link="chassis"/>
    <!-- Rotate chassis 180 deg around z if needed -->
    <origin xyz="0 0 0" rpy="0 0 3.14159"/>
  </joint>

  <joint name="imu_joint" type="fixed">
    <parent link="base_link"/>
    <child link="imu_link"/>
    <origin xyz="-0.05 0 0.16" rpy="0 0 0"/>
  </joint>

  <joint name="front_steer_joint" type="revolute">
    <parent link="chassis"/>
    <child link="steer_knuckle"/>
    <origin xyz="-0.15 0 0.03" rpy="0 0 0"/>
    <axis xyz="0 0 1"/>
    <limit lower="-0.785" upper="0.785" effort="10" velocity="3"/>
    <dynamics damping="0.5"/>
  </joint>

  <!-- Front wheel joints attached to knuckle -->
  <joint name="front_left_wheel_joint" type="continuous">
    <parent link="steer_knuckle"/>
    <child link="front_left_wheel"/>
    <origin xyz="0 0.02 -0.015" rpy="0 0 0"/>
    <axis xyz="0 -1 0"/>
    <dynamics damping="0.1" friction="0.05"/>
  </joint>

  <joint name="front_right_wheel_joint" type="continuous">
    <parent link="steer_knuckle"/>
    <child link="front_right_wheel"/>
    <origin xyz="0 -0.02 -0.015" rpy="0 0 0"/>
    <axis xyz="0 -1 0"/>
    <dynamics damping="0.1" friction="0.05"/>
  </joint>

  <!-- Rear wheel joints -->
  <joint name="left_wheel_joint" type="continuous">
    <parent link="chassis"/>
    <child link="left_wheel"/>
    <origin xyz="0.1 0.13 0.085" rpy="0 0 0"/>
    <axis xyz="0 -1 0"/>
    <dynamics damping="5.0" friction="0.5"/>
  </joint>

  <joint name="right_wheel_joint" type="continuous">
    <parent link="chassis"/>
    <child link="right_wheel"/>
    <origin xyz="0.1 -0.13 0.085" rpy="0 0 0"/>
    <axis xyz="0 -1 0"/>
    <dynamics damping="5.0" friction="0.5"/>
  </joint>

  <!-- ros2_control hardware definition -->
  <ros2_control name="GazeboSystem" type="system">
    <hardware>
      <plugin>gazebo_ros2_control/GazeboSystem</plugin>
    </hardware>

    <joint name="front_steer_joint">
      <command_interface name="position"/>
      <state_interface name="position"/>
    </joint>

    <joint name="front_left_wheel_joint">
      <state_interface name="position"/>
      <state_interface name="velocity"/>
    </joint>

    <joint name="front_right_wheel_joint">
      <state_interface name="position"/>
      <state_interface name="velocity"/>
    </joint>

    <joint name="left_wheel_joint">
      <command_interface name="velocity"/>
      <state_interface name="position"/>
      <state_interface name="velocity"/>
    </joint>

    <joint name="right_wheel_joint">
      <command_interface name="velocity"/>
      <state_interface name="position"/>
      <state_interface name="velocity"/>
    </joint>
  </ros2_control>



  <gazebo>
    <plugin name="gazebo_ros2_control" filename="libgazebo_ros2_control.so">
      <parameters>/home/pranayt/ros2_ws/latty/install/latty_chassis/share/latty_chassis/config/latty_controllers.yaml</parameters>
    </plugin>
  </gazebo>

  <gazebo reference="imu_link">
    <sensor name="imu_sensor" type="imu">
      <always_on>true</always_on>
      <update_rate>100.0</update_rate>
      <visualize>true</visualize>
      <plugin name="imu_plugin" filename="libgazebo_ros_imu_sensor.so">
        <ros>
          <namespace>/</namespace>
          <remappings>~/out:=/imu</remappings>
        </ros>
        <frame_name>imu_link</frame_name>
      </plugin>
    </sensor>
  </gazebo>

</robot>